Python 3.7.4 (default, Aug 13 2019, 20:35:49) 
[GCC 7.3.0] :: Anaconda, Inc. on linux
Type "help", "copyright", "credits" or "license" for more information.
>>> import py_cuffs
>>> py_cuffs.start()

Spectral points per block  : 42
Threads per block          : 1024
Spectral points per thread : 0

Init v : 
Loading v0.npy...
Done!
Loading da.npy...
Done!

Init wL: 
Loading log_2gs.npy...
Done!
Loading na.npy...
Done!
Initializing Lorentzian parameters  (from cache)... 
Done!

Init wG: 
Loading log_2vMm.npy...
Done!
Initializing Gaussian parameters
... 
Traceback (most recent call last):
  File "py_cuffs.pyx", line 696, in py_cuffs.init_gaussian_params
    with open(fname, 'rb') as f:
FileNotFoundError: [Errno 2] No such file or directory: 'Gaussian_minmax_55581120.dat'

During handling of the above exception, another exception occurred:

ValueError: invalid number of arguments
Exception ignored in: 'py_cuffs.init_gaussian_params'
ValueError: invalid number of arguments

Init I: 
Loading S0.npy...
Done!
Loading El.npy...
Done!

Number of lines loaded: 55581120

Allocating device memory...
Done!
Copying data to device... 
Traceback (most recent call last):
  File "<stdin>", line 1, in <module>
  File "py_cuffs.pyx", line 1264, in py_cuffs.start
    host_params_h_v0_d =        cp.array(spec_h_v0)
  File "/home/pankaj/anaconda3/lib/python3.7/site-packages/cupy/creation/from_data.py", line 43, in array
    return core.array(obj, dtype, copy, order, subok, ndmin)
  File "cupy/core/core.pyx", line 1785, in cupy.core.core.array
  File "cupy/core/core.pyx", line 1862, in cupy.core.core.array
  File "cupy/core/core.pyx", line 1937, in cupy.core.core._send_object_to_gpu
  File "cupy/core/core.pyx", line 134, in cupy.core.core.ndarray.__init__
  File "cupy/cuda/memory.pyx", line 544, in cupy.cuda.memory.alloc
  File "cupy/cuda/memory.pyx", line 1243, in cupy.cuda.memory.MemoryPool.malloc
  File "cupy/cuda/memory.pyx", line 1264, in cupy.cuda.memory.MemoryPool.malloc
  File "cupy/cuda/memory.pyx", line 1042, in cupy.cuda.memory.SingleDeviceMemoryPool.malloc
  File "cupy/cuda/memory.pyx", line 1062, in cupy.cuda.memory.SingleDeviceMemoryPool._malloc
  File "cupy/cuda/memory.pyx", line 784, in cupy.cuda.memory._try_malloc
cupy.cuda.memory.OutOfMemoryError: Out of memory allocating 444,648,960 bytes (allocated so far: 1,024 bytes).
>>> 

